<?xml version="1.0" ?>
<sdf version="1.9">
  <world name="default">

    <plugin filename="ignition-gazebo-physics-system"
            name="ignition::gazebo::systems::Physics"/>
    <plugin filename="ignition-gazebo-user-commands-system"
            name="ignition::gazebo::systems::UserCommands"/>
    <plugin filename="ignition-gazebo-scene-broadcaster-system"
            name="ignition::gazebo::systems::SceneBroadcaster"/>

    <physics name="default_physics" default="0" type="dart">
      <max_step_size>0.004</max_step_size>
      <real_time_factor>1.0</real_time_factor>
      <real_time_update_rate>250</real_time_update_rate>
    </physics>

    <gravity>0 0 -9.8</gravity>

    <light name="sun" type="directional">
      <pose>0 0 10 0 0 0</pose>
      <cast_shadows>true</cast_shadows>
      <diffuse>0.9 0.9 0.9 1</diffuse>
      <specular>0.2 0.2 0.2 1</specular>
      <direction>-0.5 0.1 -0.9</direction>
    </light>

    <model name="ground_plane">
      <static>true</static>
      <link name="link">
        <collision name="collision">
          <geometry>
            <plane>
              <normal>0 0 1</normal>
              <size>100 100</size>
            </plane>
          </geometry>
          <surface>
            <friction>
              <ode>
                <mu>100</mu>
                <mu2>50</mu2>
              </ode>
            </friction>
          </surface>
        </collision>
        <visual name="visual">
          <cast_shadows>false</cast_shadows>
          <geometry>
            <plane>
              <normal>0 0 1</normal>
              <size>100 100</size>
            </plane>
          </geometry>
          <material>
            <ambient>0.4 0.4 0.45 1</ambient>
            <diffuse>0.45 0.45 0.5 1</diffuse>
          </material>
        </visual>
      </link>
    </model>

    <model name="diff_drive_robot">
      <pose>0 0 0.11 0 0 0</pose>

      <link name="base_link">
        <inertial>
          <mass>5.0</mass>
          <inertia>
            <ixx>0.1</ixx><ixy>0</ixy><ixz>0</ixz>
            <iyy>0.1</iyy><iyz>0</iyz>
            <izz>0.1</izz>
          </inertia>
        </inertial>
        <collision name="base_collision">
          <geometry><box><size>0.4 0.3 0.1</size></box></geometry>
        </collision>
        <visual name="base_visual">
          <geometry><box><size>0.4 0.3 0.1</size></box></geometry>
          <material>
            <ambient>0.13 0.51 0.96 1</ambient>
            <diffuse>0.13 0.51 0.96 1</diffuse>
          </material>
        </visual>
      </link>

      <link name="left_wheel">
        <pose relative_to="base_link">0 0.17 0 0 0 0</pose>
        <inertial>
          <mass>0.5</mass>
          <inertia>
            <ixx>0.001</ixx><ixy>0</ixy><ixz>0</ixz>
            <iyy>0.001</iyy><iyz>0</iyz>
            <izz>0.001</izz>
          </inertia>
        </inertial>
        <collision name="left_wheel_collision">
          <pose>0 0 0 1.5707963 0 0</pose>
          <geometry><cylinder><radius>0.1</radius><length>0.04</length></cylinder></geometry>
          <surface>
            <friction>
              <ode><mu>1.0</mu><mu2>1.0</mu2></ode>
            </friction>
          </surface>
        </collision>
        <visual name="left_wheel_visual">
          <pose>0 0 0 1.5707963 0 0</pose>
          <geometry><cylinder><radius>0.1</radius><length>0.04</length></cylinder></geometry>
          <material>
            <ambient>0.1 0.1 0.1 1</ambient>
            <diffuse>0.1 0.1 0.1 1</diffuse>
          </material>
        </visual>
      </link>

      <link name="right_wheel">
        <pose relative_to="base_link">0 -0.17 0 0 0 0</pose>
        <inertial>
          <mass>0.5</mass>
          <inertia>
            <ixx>0.001</ixx><ixy>0</ixy><ixz>0</ixz>
            <iyy>0.001</iyy><iyz>0</iyz>
            <izz>0.001</izz>
          </inertia>
        </inertial>
        <collision name="right_wheel_collision">
          <pose>0 0 0 1.5707963 0 0</pose>
          <geometry><cylinder><radius>0.1</radius><length>0.04</length></cylinder></geometry>
          <surface>
            <friction>
              <ode><mu>1.0</mu><mu2>1.0</mu2></ode>
            </friction>
          </surface>
        </collision>
        <visual name="right_wheel_visual">
          <pose>0 0 0 1.5707963 0 0</pose>
          <geometry><cylinder><radius>0.1</radius><length>0.04</length></cylinder></geometry>
          <material>
            <ambient>0.1 0.1 0.1 1</ambient>
            <diffuse>0.1 0.1 0.1 1</diffuse>
          </material>
        </visual>
      </link>

      <link name="caster">
        <pose relative_to="base_link">0.15 0 -0.05 0 0 0</pose>
        <inertial>
          <mass>0.1</mass>
          <inertia>
            <ixx>0.0001</ixx><ixy>0</ixy><ixz>0</ixz>
            <iyy>0.0001</iyy><iyz>0</iyz>
            <izz>0.0001</izz>
          </inertia>
        </inertial>
        <collision name="caster_collision">
          <geometry><sphere><radius>0.05</radius></sphere></geometry>
          <surface>
            <friction>
              <ode><mu>0.0</mu><mu2>0.0</mu2></ode>
            </friction>
          </surface>
        </collision>
        <visual name="caster_visual">
          <geometry><sphere><radius>0.05</radius></sphere></geometry>
          <material>
            <ambient>0.55 0.55 0.55 1</ambient>
            <diffuse>0.55 0.55 0.55 1</diffuse>
          </material>
        </visual>
      </link>

      <joint name="left_wheel_joint" type="revolute">
        <parent>base_link</parent>
        <child>left_wheel</child>
        <axis>
          <xyz>0 1 0</xyz>
          <dynamics>
            <friction>0.05</friction>
          </dynamics>
          <limit>
            <lower>-1e16</lower>
            <upper>1e16</upper>
          </limit>
        </axis>
      </joint>

      <joint name="right_wheel_joint" type="revolute">
        <parent>base_link</parent>
        <child>right_wheel</child>
        <axis>
          <xyz>0 1 0</xyz>
          <dynamics>
            <friction>0.05</friction>
          </dynamics>
          <limit>
            <lower>-1e16</lower>
            <upper>1e16</upper>
          </limit>
        </axis>
      </joint>

      <joint name="caster_joint" type="fixed">
        <parent>base_link</parent>
        <child>caster</child>
      </joint>

      <plugin filename="ignition-gazebo-diff-drive-system"
              name="ignition::gazebo::systems::DiffDrive">
        <left_joint>left_wheel_joint</left_joint>
        <right_joint>right_wheel_joint</right_joint>
        <wheel_separation>0.34</wheel_separation>
        <wheel_radius>0.1</wheel_radius>
        <odom_publish_frequency>30</odom_publish_frequency>
        <topic>/cmd_vel</topic>
        <odom_topic>/odom</odom_topic>
        <frame_id>odom</frame_id>
        <child_frame_id>base_link</child_frame_id>
      </plugin>
    </model>

  </world>
</sdf>
