<?xml version="1.0" ?>
<sdf version="1.6">
  <world name="default">

    <light name="sun" type="directional">
      <pose>0 0 10 0 0 0</pose>
      <diffuse>1 1 1 1</diffuse>
      <specular>0.2 0.2 0.2 1</specular>
      <direction>-0.5 0.1 -0.9</direction>
      <cast_shadows>true</cast_shadows>
    </light>

    <model name="ground_plane">
      <static>true</static>
      <link name="link">
        <collision name="collision">
          <geometry>
            <plane>
              <normal>0 0 1</normal>
              <size>100 100</size>
            </plane>
          </geometry>
          <surface>
            <friction>
              <ode>
                <mu>100</mu>
                <mu2>50</mu2>
              </ode>
            </friction>
          </surface>
        </collision>
        <visual name="visual">
          <cast_shadows>false</cast_shadows>
          <geometry>
            <plane>
              <normal>0 0 1</normal>
              <size>100 100</size>
            </plane>
          </geometry>
          <material>
            <ambient>0.5 0.5 0.5 1</ambient>
            <diffuse>0.5 0.5 0.5 1</diffuse>
          </material>
        </visual>
      </link>
    </model>

    <physics name="default_physics" default="0" type="ode">
      <max_step_size>0.004</max_step_size>
      <real_time_factor>1.0</real_time_factor>
      <real_time_update_rate>250</real_time_update_rate>
    </physics>

    <model name="diff_drive_robot">
      <pose>0 0 0.11 0 0 0</pose>

      <link name="base_link">
        <inertial>
          <mass>5.0</mass>
          <inertia>
            <ixx>0.1</ixx><ixy>0</ixy><ixz>0</ixz>
            <iyy>0.1</iyy><iyz>0</iyz>
            <izz>0.1</izz>
          </inertia>
        </inertial>
        <collision name="base_collision">
          <geometry><box><size>0.4 0.3 0.1</size></box></geometry>
        </collision>
        <visual name="base_visual">
          <geometry><box><size>0.4 0.3 0.1</size></box></geometry>
          <material>
            <ambient>0.2 0.4 0.8 1</ambient>
            <diffuse>0.2 0.4 0.8 1</diffuse>
          </material>
        </visual>
      </link>

      <link name="left_wheel">
        <pose>0 0.17 0 0 0 0</pose>
        <inertial>
          <mass>0.5</mass>
          <inertia>
            <ixx>0.001</ixx><ixy>0</ixy><ixz>0</ixz>
            <iyy>0.001</iyy><iyz>0</iyz>
            <izz>0.001</izz>
          </inertia>
        </inertial>
        <collision name="left_wheel_collision">
          <pose>0 0 0 1.5707963 0 0</pose>
          <geometry><cylinder><radius>0.1</radius><length>0.04</length></cylinder></geometry>
          <surface>
            <friction><ode><mu>1.0</mu><mu2>1.0</mu2></ode></friction>
          </surface>
        </collision>
        <visual name="left_wheel_visual">
          <pose>0 0 0 1.5707963 0 0</pose>
          <geometry><cylinder><radius>0.1</radius><length>0.04</length></cylinder></geometry>
          <material>
            <ambient>0.1 0.1 0.1 1</ambient>
            <diffuse>0.1 0.1 0.1 1</diffuse>
          </material>
        </visual>
      </link>

      <link name="right_wheel">
        <pose>0 -0.17 0 0 0 0</pose>
        <inertial>
          <mass>0.5</mass>
          <inertia>
            <ixx>0.001</ixx><ixy>0</ixy><ixz>0</ixz>
            <iyy>0.001</iyy><iyz>0</iyz>
            <izz>0.001</izz>
          </inertia>
        </inertial>
        <collision name="right_wheel_collision">
          <pose>0 0 0 1.5707963 0 0</pose>
          <geometry><cylinder><radius>0.1</radius><length>0.04</length></cylinder></geometry>
          <surface>
            <friction><ode><mu>1.0</mu><mu2>1.0</mu2></ode></friction>
          </surface>
        </collision>
        <visual name="right_wheel_visual">
          <pose>0 0 0 1.5707963 0 0</pose>
          <geometry><cylinder><radius>0.1</radius><length>0.04</length></cylinder></geometry>
          <material>
            <ambient>0.1 0.1 0.1 1</ambient>
            <diffuse>0.1 0.1 0.1 1</diffuse>
          </material>
        </visual>
      </link>

      <link name="caster">
        <pose>0.15 0 -0.05 0 0 0</pose>
        <inertial>
          <mass>0.1</mass>
          <inertia>
            <ixx>0.0001</ixx><ixy>0</ixy><ixz>0</ixz>
            <iyy>0.0001</iyy><iyz>0</iyz>
            <izz>0.0001</izz>
          </inertia>
        </inertial>
        <collision name="caster_collision">
          <geometry><sphere><radius>0.05</radius></sphere></geometry>
          <surface>
            <friction><ode><mu>0.0</mu><mu2>0.0</mu2></ode></friction>
          </surface>
        </collision>
        <visual name="caster_visual">
          <geometry><sphere><radius>0.05</radius></sphere></geometry>
          <material>
            <ambient>0.5 0.5 0.5 1</ambient>
            <diffuse>0.5 0.5 0.5 1</diffuse>
          </material>
        </visual>
      </link>

      <joint name="left_wheel_joint" type="revolute">
        <parent>base_link</parent>
        <child>left_wheel</child>
        <axis>
          <xyz>0 1 0</xyz>
          <dynamics><friction>0.05</friction></dynamics>
          <limit><lower>-1e16</lower><upper>1e16</upper></limit>
        </axis>
      </joint>

      <joint name="right_wheel_joint" type="revolute">
        <parent>base_link</parent>
        <child>right_wheel</child>
        <axis>
          <xyz>0 1 0</xyz>
          <dynamics><friction>0.05</friction></dynamics>
          <limit><lower>-1e16</lower><upper>1e16</upper></limit>
        </axis>
      </joint>

      <joint name="caster_joint" type="fixed">
        <parent>base_link</parent>
        <child>caster</child>
      </joint>

      <plugin name="diff_drive" filename="libgazebo_ros_diff_drive.so">
        <ros>
          <namespace>/</namespace>
          <remapping>cmd_vel:=cmd_vel</remapping>
          <remapping>odom:=odom</remapping>
        </ros>
        <update_rate>30</update_rate>
        <num_wheel_pairs>1</num_wheel_pairs>
        <left_joint>left_wheel_joint</left_joint>
        <right_joint>right_wheel_joint</right_joint>
        <wheel_separation>0.34</wheel_separation>
        <wheel_diameter>0.2</wheel_diameter>
        <max_wheel_torque>5.0</max_wheel_torque>
        <max_wheel_acceleration>2.0</max_wheel_acceleration>
        <publish_odom>true</publish_odom>
        <publish_odom_tf>true</publish_odom_tf>
        <publish_wheel_tf>false</publish_wheel_tf>
        <odometry_frame>odom</odometry_frame>
        <robot_base_frame>base_link</robot_base_frame>
      </plugin>

    </model>

  </world>
</sdf>
